<?xml version="1.0"?>
<robot name="robot" >
  <link name="link_chassis">
    <!-- pose and inertial -->
    <pose>0 0 0.1 0 0 0</pose>
    <inertial>
      <mass value="1"/>
      <origin rpy="0 0 0" xyz="0 0 0.1"/>
      <inertia ixx="0.0395416666667" ixy="0" ixz="0" iyy="0.106208333333" iyz="0" izz="0.106208333333"/>
    </inertial>
    <!-- body -->
    <collision name="collision_chassis">
      <geometry>
        <box size="0.5 0.3 0.07"/>
      </geometry>
    </collision>
    <visual>
      <origin rpy="0 0 0" xyz="0 0 0"/>
      <geometry>
        <box size="0.5 0.3 0.07"/>
      </geometry>
    </visual>
    <!-- front wheels
    <collision name="right_front_collision">
      <origin rpy="1.57 0 0" xyz="0.15 0.15 0"/>
      <geometry>
        <cylinder length="0.06" radius="0.08"/>
      </geometry>
      <surface>
        <friction>
          <ode>
            <mu>0</mu>
            <mu2>0</mu2>
            <slip1>0.0</slip1>
            <slip2>0.0</slip2>
          </ode>
        </friction>
      </surface>
    </collision>
    <visual name="right_front_visual">
      <origin rpy="1.57 0 0" xyz="0.15 0.15 0"/>
      <geometry>
        <cylinder length="0.06" radius="0.08"/>
      </geometry>
    </visual>
    <collision name="left_front_collision">
      <origin rpy="1.57 0 0" xyz="0.15 -0.15 0"/>
      <geometry>
        <cylinder length="0.06" radius="0.08"/>
      </geometry>
      <surface>
        <friction>
          <ode>
            <mu>0</mu>
            <mu2>0</mu2>
            <slip1>0.0</slip1>
            <slip2>0.0</slip2>
          </ode>
        </friction>
      </surface>
    </collision>
    <visual name="left_front_visual">
      <origin rpy="1.57 0 0" xyz="0.15 -0.15 0"/>
      <geometry>
        <cylinder length="0.06" radius="0.08"/>
      </geometry>
    </visual>-->
  </link>
  <!-- right wheel back-->
  <joint name="joint_right_wheel" type="continuous">
    <origin rpy="0 0 0" xyz="-0.15 0.18 0"/>
    <child link="link_right_wheel"/>
    <parent link="link_chassis"/>
    <axis rpy="0 0 0" xyz="0 1 0"/>
    <limit effort="10000" velocity="1000"/>
    <joint_properties damping="1.0" friction="5.0"/>
  </joint>

  <link name="link_right_wheel">
    <inertial>
      <mass value="0.2"/>
      <origin rpy="0 1.5707 1.5707" xyz="0 0 0"/>
      <inertia ixx="0.000526666666667" ixy="0" ixz="0" iyy="0.000526666666667" iyz="0" izz="0.001"/>
    </inertial>
    <collision name="link_right_wheel_collision">
      <origin rpy="0 1.5707 1.5707" xyz="0 0 0"/>
      <geometry>
        <cylinder length="0.06" radius="0.1"/>
      </geometry>
    </collision>
    <visual name="link_right_wheel_visual">
      <origin rpy="0 1.5707 1.5707" xyz="0 0 0"/>
      <geometry>
        <cylinder length="0.06" radius="0.1"/>
      </geometry>
    </visual>
  </link>
  
  
  
  <!-- left wheel back-->
  <joint name="joint_left_wheel" type="continuous">
    <origin rpy="0 0 0" xyz="-0.15 -0.18 0"/>
    <child link="link_left_wheel"/>
    <parent link="link_chassis"/>
    <axis rpy="0 0 0" xyz="0 1 0"/>
    <limit effort="10000" velocity="1000"/>
    <joint_properties damping="1.0" friction="5.0"/>
  </joint>

  <link name="link_left_wheel">
    <inertial>
      <mass value="0.2"/>
      <origin rpy="0 1.5707 1.5707" xyz="0 0 0"/>
      <inertia ixx="0.000526666666667" ixy="0" ixz="0" iyy="0.000526666666667" iyz="0" izz="0.001"/>
    </inertial>
    <collision name="link_left_wheel_collision">
      <origin rpy="0 1.5707 1.5707" xyz="0 0 0"/>
      <geometry>
        <cylinder length="0.06" radius="0.1"/>
      </geometry>
    </collision>
    <visual name="link_left_wheel_visual">
      <origin rpy="0 1.5707 1.5707" xyz="0 0 0"/>
      <geometry>
        <cylinder length="0.06" radius="0.1"/>
      </geometry>
    </visual>
  </link>
  
 
  <!-- right wheel front-->
  <joint name="joint_right_wheelf" type="continuous">
    <origin rpy="0 0 0" xyz="0.15 0.18 0"/>
    <child link="link_right_wheelf"/>
    <parent link="link_chassis"/>
    <axis rpy="0 0 0" xyz="0 1 0"/>
    <limit effort="10000" velocity="1000"/>
    <joint_properties damping="0.0" friction="0.0"/>
  </joint>

  <link name="link_right_wheelf">
    <inertial>
      <mass value="0.0001"/>
      <origin rpy="0 1.5707 1.5707" xyz="0 0 0"/>
      <inertia ixx="0.000526666666667" ixy="0" ixz="0" iyy="0.000526666666667" iyz="0" izz="0.001"/>
    </inertial>
    <collision name="link_right_wheelf_collision">
      <origin rpy="0 1.5707 1.5707" xyz="0 0 0"/>
      <geometry>
        <cylinder length="0.06" radius="0.1"/>
      </geometry>
    </collision>
    <visual name="link_right_wheelf_visual">
      <origin rpy="0 1.5707 1.5707" xyz="0 0 0"/>
      <geometry>
        <cylinder length="0.06" radius="0.1"/>
      </geometry>
    </visual>
  </link>
  
  <!-- left wheel front-->
  <joint name="joint_left_wheelf" type="continuous">
    <origin rpy="0 0 0" xyz="0.15 -0.18 0"/>
    <child link="link_left_wheelf"/>
    <parent link="link_chassis"/>
    <axis rpy="0 0 0" xyz="0 1 0"/>
    <limit effort="10000" velocity="1000"/>
    <joint_properties damping="0.0" friction="0.0"/>
  </joint>

  <link name="link_left_wheelf">
    <inertial>
      <mass value="0.0001"/>
      <origin rpy="0 1.5707 1.5707" xyz="0 0 0"/>
      <inertia ixx="0.000526666666667" ixy="0" ixz="0" iyy="0.000526666666667" iyz="0" izz="0.001"/>
    </inertial>
    <collision name="link_left_wheelf_collision">
      <origin rpy="0 1.5707 1.5707" xyz="0 0 0"/>
      <geometry>
        <cylinder length="0.06" radius="0.1"/>
      </geometry>
    </collision>
    <visual name="link_left_wheef_visual">
      <origin rpy="0 1.5707 1.5707" xyz="0 0 0"/>
      <geometry>
        <cylinder length="0.06" radius="0.1"/>
      </geometry>
    </visual>
  </link>
  

    <!-- laser sensor -->
       <link name="laser_sensor">
    <inertial>
      <mass value="0.01"/>
      <origin rpy="0 0 0" xyz="0 0 0"/>
      <inertia ixx="0.000526666666667" ixy="0" ixz="0" iyy="0.000526666666667" iyz="0" izz="0.001"/>
    </inertial>
    <collision name="laser_sensor_collision">
      <origin rpy=" 0 0 0" xyz="0.0 0 0.0"/>
      <geometry>
        <box size="0.05 0.05 0.19"/>
      </geometry>
    </collision>
    <visual name="laser_sensor_visual">
      <origin rpy=" 0 0 0" xyz="0.0 0 0.0"/>
      <geometry>
        <box size="0.05 0.05 0.19"/>
      </geometry>
    </visual>
  </link>
  
   <joint name="joint_laser_sensor" type="fixed">
    <origin rpy="0 0 0" xyz="0.20 0 0.13"/>
    <child link="laser_sensor"/>
    <parent link="link_chassis"/>
    <axis rpy="0 0 0" xyz="0 1 0"/>
    <limit effort="10000" velocity="1000"/>
    <joint_properties damping="1.0" friction="1.0"/>
  </joint>

  <gazebo>
    <plugin filename="libgazebo_ros_diff_drive.so" name="differential_drive_controller">
      <legacyMode>false</legacyMode>
      <alwaysOn>true</alwaysOn>
      <updateRate>10</updateRate>
      <leftJoint>joint_right_wheel</leftJoint>
      <rightJoint>joint_left_wheel</rightJoint>
      <wheelSeparation>0.3</wheelSeparation>
      <wheelDiameter>0.2</wheelDiameter>
      <torque>0.1</torque>
      <commandTopic>cmd_vel</commandTopic>
      <odometryTopic>odom</odometryTopic>
      <odometryFrame>odom</odometryFrame>
      <robotBaseFrame>link_chassis</robotBaseFrame>
    </plugin>
  </gazebo>
  <!-- hokuyo -->
  <gazebo reference="laser_sensor">
    <sensor type="ray" name="head_hokuyo_sensor">
      <pose>0 0 0 0 0 0</pose>
      <visualize>false</visualize>
      <update_rate>20</update_rate>
      <ray>
        <scan>
          <horizontal>
            <samples>720</samples>
            <resolution>1</resolution>
            <min_angle>-1.570796</min_angle>
            <max_angle>1.570796</max_angle>
          </horizontal>
        </scan>
        <range>
          <min>0.10</min>
          <max>10.0</max>
          <resolution>0.01</resolution>
        </range>
        <noise>
          <type>gaussian</type>
          <mean>0.0</mean>
          <stddev>0.01</stddev>
        </noise>
      </ray>
      <plugin name="gazebo_ros_head_hokuyo_controller" filename="libgazebo_ros_laser.so">
        <topicName>/robot/laser/scan</topicName>
        <frameName>laser_sensor</frameName>
      </plugin>
    </sensor>
  </gazebo>
</robot>